Workbook

Sheet MASTER_DATABASE
A1: Devmobile Stores and Common Service Center & Aadhaar Centre — MASTER DATABASE (one row = one service)
A2: Blue header = type / choose here (editable). Green header + grey cells = formula (do not type over). Add a new service: copy an existing row (Ctrl+C, paste under the last row) then edit. Documents are edited in SERVICE_DOCUMENTS.
A3: Service ID | B3: Service Center | C3: Main Category | D3: Sub Category | E3: Service Name English | F3: Service Name Hindi | G3: Short Description | H3: Detailed Description | I3: Service Availability | J3: Availability Status | K3: Authorization Required | L3: Authorization Status | M3: Required Documents | N3: Additional Documents | O3: Customer Eligibility | P3: Process / How It Works | Q3: Estimated Processing Time | R3: Government Fee | S3: Shop Service Charge | T3: Total Customer Charge | U3: Charge Status | V3: Price Display on Website | W3: Payment Mode | X3: Online / Offline / Both | Y3: Portal Required | Z3: Portal Name | AA3: Customer Must Visit Shop | AB3: Contact Required | AC3: WhatsApp Available | AD3: Call Available | AE3: Booking Required | AF3: Appointment Required | AG3: Service Status | AH3: Website Visible | AI3: Featured Service | AJ3: Popular Service | AK3: Homepage Display | AL3: Website Category | AM3: Website Subcategory | AN3: Search Keywords | AO3: Website Slug | AP3: Icon | AQ3: Display Order | AR3: FAQ | AS3: Important Note | AT3: Terms / Conditions | AU3: Last Verified Date | AV3: Verification Status | AW3: Internal Remarks | AX3: SEO Title | AY3: SEO Description | AZ3: Hindi Keywords | BA3: English Keywords | BB3: Service Image | BC3: Category Icon | BD3: Service Page | BE3: Live on Website | BF3: Benefits | BG3: Customer Action | BH3: Center Key (auto) | BI3: Featured Seq (auto) | BJ3: Popular Seq (auto) | BK3: Homepage Seq (auto) | BL3: To Verify Seq (auto)
A4: AAD-001 | B4: Aadhaar Centre | C4: Aadhaar Services | D4: Enrolment | E4: New Aadhaar Enrolment – Adult (18+ years) | F4: नया आधार नामांकन – वयस्क (18+ वर्ष) | G4: Get New Aadhaar Enrolment – Adult (18+ years) done at our Aadhaar Centre. | H4: Fresh Aadhaar enrolment for adults. The operator captures demographic details, fingerprints, iris and photograph, and gives an enrolment acknowledgement. | I4: Authorization Required | J4: =IFERROR(INDEX(AVAILABILITY_MASTER!$C$4:$C$10,MATCH(I4,AVAILABILITY_MASTER!$A$4:$A$10,0)),"To Be Confirmed") -> Please Confirm at Shop | K4: Yes | L4: To Verify | M4: =IFERROR(INDEX(SERVICE_DOCUMENTS!$S$4:$S$1000,MATCH(A4,SERVICE_DOCUMENTS!$A$4:$A$1000,0))&"","") -> ✓ Identity Proof ✓ Address Proof ✓ Date of Birth Proof ✓ Customer Presence for Biometrics | N4: =IFERROR(INDEX(SERVICE_DOCUMENTS!$T$4:$T$1000,MATCH(A4,SERVICE_DOCUMENTS!$A$4:$A$1000,0))&"","") -> • Active Mobile Number (If Applicable) | O4: Residents aged 18 years or above who do not yet have an Aadhaar. | P4: Step 1 → Adult applicant comes in person with original identity, address and date-of-birth documents. Step 2 → Operator fills the enrolment form with your details. Step 3 → Fingerprints, iris and photograph are captured. Step 4 → You review the entered details; sign the consent. Step 5 → Collect the enrolment slip (EID) and track the status; Aadhaar is delivered after UIDAI processing. | Q4: Depends on Department | R4: To Verify | S4: To Verify | T4: =IF(AND(OR(ISNUMBER(R4),R4="N/A"),OR(ISNUMBER(S4),S4="N/A"),OR(ISNUMBER(R4),ISNUMBER(S4))),N(R4)+N(S4),"To Verify") -> To Verify | U4: To Verify | V4: No | W4: Depends on Service | X4: Offline | Y4: No | AA4: Yes | AB4: Yes | AC4: To Verify | AD4: To Verify | AE4: No | AF4: To Verify | AG4: To Verify | AH4: No | AI4: No | AJ4: No | AK4: No | AL4: Aadhaar Centre | AM4: Enrolment | AN4: =BA4&", "&AZ4 -> New Aadhaar Enrolment – Adult (18+ years), Aadhaar Centre, Devmobile Stores, नया आधार नामांकन – वयस्क (18+ वर्ष), आधार सेंटर, सेवा | AO4: new-aadhaar-enrolment-adult-18-years | AP4: 🆕 | AQ4: 10 | AR4: Q1: Do I need to visit in person? A1: Yes, biometrics are captured at the centre. Q2: How long does Aadhaar take? A2: Processing is done by UIDAI; the time depends on the department. | AS4: Aadhaar services depend on UIDAI operator authorization. Please confirm with the shop before visiting. | AT4: Fees, documents and processing time are subject to change as per government / bank / portal rules. Final charges are confirmed at the shop before the service starts. | AV4: To Verify | AW4: Fresh enrolment needs valid PoI/PoA/DoB documents as per current UIDAI list | AX4: New Aadhaar Enrolment – Adult (18+ years) Service | Devmobile Stores | AY4: New Aadhaar Enrolment – Adult (18+ years) (नया आधार नामांकन – वयस्क (18+ वर्ष)) at Devmobile Stores and Common Service Center & Aadhaar Centre. Check required documents, charges and process before you visit. | AZ4: नया आधार नामांकन – वयस्क (18+ वर्ष), आधार सेंटर, सेवा | BA4: New Aadhaar Enrolment – Adult (18+ years), Aadhaar Centre, Devmobile Stores | BC4: =IFERROR(INDEX(CATEGORY_MASTER!$C$4:$C$30,MATCH(B4,CATEGORY_MASTER!$A$4:$A$30,0)),"") -> 🪪 | BD4: ="/services/"&AO4 -> /services/new-aadhaar-enrolment-adult-18-years | BE4: =IF(AND(AH4="Yes",AG4="Active",I4<>"Not Available"),"LIVE","HIDDEN") -> HIDDEN | BF4: Get your first Aadhaar • Biometric capture done at the centre • Acknowledgement slip for tracking | BG4: Check Documents | BH4: =B4&"|"&COUNTIF($B$4:B4,B4) -> Aadhaar Centre|1 | BI4: =IF(AND(AI4="Yes",BE4="LIVE"),COUNTIFS($AI$4:AI4,"Yes",$BE$4:BE4,"LIVE"),"") | BJ4: =IF(AND(AJ4="Yes",BE4="LIVE"),COUNTIFS($AJ$4:AJ4,"Yes",$BE$4:BE4,"LIVE"),"") | BK4: =IF(AND(AK4="Yes",BE4="LIVE"),COUNTIFS($AK$4:AK4,"Yes",$BE$4:BE4,"LIVE"),"") | BL4: =IF(I4="To Verify",COUNTIF($I$4:I4,"To Verify"),"")
A5: AAD-002 | B5: Aadhaar Centre | C5: Aadhaar Services | D5: Enrolment | E5: New Aadhaar Enrolment – Child (5 to 17 years) | F5: नया आधार नामांकन – बच्चा (5 से 17 वर्ष) | G5: Get New Aadhaar Enrolment – Child (5 to 17 years) done at our Aadhaar Centre. | H5: New Aadhaar enrolment for a child between 5 and 17 years with biometric capture. | I5: Authorization Required | J5: =IFERROR(INDEX(AVAILABILITY_MASTER!$C$4:$C$10,MATCH(I5,AVAILABILITY_MASTER!$A$4:$A$10,0)),"To Be Confirmed") -> Please Confirm at Shop | K5: Yes | L5: To Verify | M5: =IFERROR(INDEX(SERVICE_DOCUMENTS!$S$4:$S$1000,MATCH(A5,SERVICE_DOCUMENTS!$A$4:$A$1000,0))&"","") -> ✓ Parent / Guardian Aadhaar ✓ Birth Certificate ✓ Customer Presence for Biometrics | N5: =IFERROR(INDEX(SERVICE_DOCUMENTS!$T$4:$T$1000,MATCH(A5,SERVICE_DOCUMENTS!$A$4:$A$1000,0))&"","") -> • Address Proof (If Applicable) | O5: Children aged 5 to 17 years without an Aadhaar. | P5: Step 1 → Parent / guardian brings the child with the child's birth proof and the parent's Aadhaar. Step 2 → Operator fills the child's enrolment form. Step 3 → Child's fingerprints, iris and photograph are captured. Step 4 → Parent reviews and signs the consent. Step 5 → Collect the enrolment slip (EID) and track the status. | Q5: Depends on Department | R5: To Verify | S5: To Verify | T5: =IF(AND(OR(ISNUMBER(R5),R5="N/A"),OR(ISNUMBER(S5),S5="N/A"),OR(ISNUMBER(R5),ISNUMBER(S5))),N(R5)+N(S5),"To Verify") -> To Verify | U5: To Verify | V5: No | W5: Depends on Service | X5: Offline | Y5: No | AA5: Yes | AB5: Yes | AC5: To Verify | AD5: To Verify | AE5: No | AF5: To Verify | AG5: To Verify | AH5: No | AI5: No | AJ5: No | AK5: No | AL5: Aadhaar Centre | AM5: Enrolment | AN5: =BA5&", "&AZ5 -> New Aadhaar Enrolment – Child (5 to 17 years), Aadhaar Centre, Devmobile Stores, नया आधार नामांकन – बच्चा (5 से 17 वर्ष), आधार सेंटर, सेवा | AO5: new-aadhaar-enrolment-child-5-to-17-years | AP5: 🆕 | AQ5: 20 | AR5: Q1: Who should accompany the child? A1: A parent or guardian with their Aadhaar. | AS5: Aadhaar services depend on UIDAI operator authorization. Please confirm with the shop before visiting. | AT5: Fees, documents and processing time are subject to change as per government / bank / portal rules. Final charges are confirmed at the shop before the service starts. | AV5: To Verify | AW5: Biometrics captured; mandatory biometric update applies at age 15 | AX5: New Aadhaar Enrolment – Child (5 to 17 years) Service | Devmobile Stores | AY5: New Aadhaar Enrolment – Child (5 to 17 years) (नया आधार नामांकन – बच्चा (5 से 17 वर्ष)) at Devmobile Stores and Common Service Center & Aadhaar Centre. Check required documents, charges and process before you visit. | AZ5: नया आधार नामांकन – बच्चा (5 से 17 वर्ष), आधार सेंटर, सेवा | BA5: New Aadhaar Enrolment – Child (5 to 17 years), Aadhaar Centre, Devmobile Stores | BC5: =IFERROR(INDEX(CATEGORY_MASTER!$C$4:$C$30,MATCH(B5,CATEGORY_MASTER!$A$4:$A$30,0)),"") -> 🪪 | BD5: ="/services/"&AO5 -> /services/new-aadhaar-enrolment-child-5-to-17-years | BE5: =IF(AND(AH5="Yes",AG5="Active",I5<>"Not Available"),"LIVE","HIDDEN") -> HIDDEN | BF5: Aadhaar for school / scholarship needs • Child biometrics captured • Acknowledgement slip | BG5: Check Documents | BH5: =B5&"|"&COUNTIF($B$4:B5,B5) -> Aadhaar Centre|2 | BI5: =IF(AND(AI5="Yes",BE5="LIVE"),COUNTIFS($AI$4:AI5,"Yes",$BE$4:BE5,"LIVE"),"") | BJ5: =IF(AND(AJ5="Yes",BE5="LIVE"),COUNTIFS($AJ$4:AJ5,"Yes",$BE$4:BE5,"LIVE"),"") | BK5: =IF(AND(AK5="Yes",BE5="LIVE"),COUNTIFS($AK$4:AK5,"Yes",$BE$4:BE5,"LIVE"),"") | BL5: =IF(I5="To Verify",COUNTIF($I$4:I5,"To Verify"),"")
A6: AAD-003 | B6: Aadhaar Centre | C6: Aadhaar Services | D6: Enrolment | E6: New Aadhaar Enrolment – Child (0 to 5 years, Baal Aadhaar) | F6: नया आधार नामांकन – बच्चा (0 से 5 वर्ष, बाल आधार) | G6: Get New Aadhaar Enrolment – Child (0 to 5 years, Baal Aadhaar) done at our Aadhaar Centre. | H6: Baal Aadhaar enrolment for newborns and children below 5 years, linked to a parent's Aadhaar. | I6: Authorization Required | J6: =IFERROR(INDEX(AVAILABILITY_MASTER!$C$4:$C$10,MATCH(I6,AVAILABILITY_MASTER!$A$4:$A$10,0)),"To Be Confirmed") -> Please Confirm at Shop | K6: Yes | L6: To Verify | M6: =IFERROR(INDEX(SERVICE_DOCUMENTS!$S$4:$S$1000,MATCH(A6,SERVICE_DOCUMENTS!$A$4:$A$1000,0))&"","") -> ✓ Parent / Guardian Aadhaar ✓ Birth Certificate ✓ Customer Presence for Biometrics | N6: =IFERROR(INDEX(SERVICE_DOCUMENTS!$T$4:$T$1000,MATCH(A6,SERVICE_DOCUMENTS!$A$4:$A$1000,0))&"","") -> • Address Proof (If Applicable) | O6: Children below 5 years (Baal Aadhaar). | P6: Step 1 → Parent brings the child (under 5 years) with the child's birth proof and the parent's Aadhaar. Step 2 → Operator fills the child's enrolment form linked to the parent's Aadhaar. Step 3 → Child's photograph is captured (fingerprints / iris are not captured under 5 years). Step 4 → Parent reviews and signs the consent. Step 5 → Collect the enrolment slip (EID) and track the status. | Q6: Depends on Department | R6: To Verify | S6: To Verify | T6: =IF(AND(OR(ISNUMBER(R6),R6="N/A"),OR(ISNUMBER(S6),S6="N/A"),OR(ISNUMBER(R6),ISNUMBER(S6))),N(R6)+N(S6),"To Verify") -> To Verify | U6: To Verify | V6: No | W6: Depends on Service | X6: Offline | Y6: No | AA6: Yes | AB6: Yes | AC6: To Verify | AD6: To Verify | AE6: No | AF6: To Verify | AG6: To Verify | AH6: No | AI6: No | AJ6: No | AK6: No | AL6: Aadhaar Centre | AM6: Enrolment | AN6: =BA6&", "&AZ6 -> New Aadhaar Enrolment – Child (0 to 5 years, Baal Aadhaar), Aadhaar Centre, Devmobile Stores, नया आधार नामांकन – बच्चा (0 से 5 वर्ष, बाल आधार), आधार सेंटर, सेवा | AO6: new-aadhaar-enrolment-child-0-to-5-years-baal-aadhaar | AP6: 🆕 | AQ6: 30 | AR6: Q1: Is a biometric needed for a baby? A1: Under 5 years, biometrics are not captured; a mandatory biometric update is done later. | AS6: Aadhaar services depend on UIDAI operator authorization. Please confirm with the shop before visiting. | AT6: Fees, documents and processing time are subject to change as per government / bank / portal rules. Final charges are confirmed at the shop before the service starts. | AV6: To Verify | AW6: Biometrics are not captured below 5 years; parent's Aadhaar and child's proof required | AX6: New Aadhaar Enrolment – Child (0 to 5 years, Baal Aadhaar) Service | Devmobile Stores | AY6: New Aadhaar Enrolment – Child (0 to 5 years, Baal Aadhaar) (नया आधार नामांकन – बच्चा (0 से 5 वर्ष, बाल आधार)) at Devmobile Stores and Common Service Center & Aadhaar Centre. Check required documents, charges and process before you visit. | AZ6: नया आधार नामांकन – बच्चा (0 से 5 वर्ष, बाल आधार), आधार सेंटर, सेवा | BA6: New Aadhaar Enrolment – Child (0 to 5 years, Baal Aadhaar), Aadhaar Centre, Devmobile Stores | BC6: =IFERROR(INDEX(CATEGORY_MASTER!$C$4:$C$30,MATCH(B6,CATEGORY_MASTER!$A$4:$A$30,0)),"") -> 🪪 | BD6: ="/services/"&AO6 -> /services/new-aadhaar-enrolment-child-0-to-5-years-baal-aadhaar | BE6: =IF(AND(AH6="Yes",AG6="Active",I6<>"Not Available"),"LIVE","HIDDEN") -> HIDDEN | BF6: Early Aadhaar for infants • No biometrics needed for very young children • Acknowledgement slip | BG6: Check Documents | BH6: =B6&"|"&COUNTIF($B$4:B6,B6) -> Aadhaar Centre|3 | BI6: =IF(AND(AI6="Yes",BE6="LIVE"),COUNTIFS($AI$4:AI6,"Yes",$BE$4:BE6,"LIVE"),"") | BJ6: =IF(AND(AJ6="Yes",BE6="LIVE"),COUNTIFS($AJ$4:AJ6,"Yes",$BE$4:BE6,"LIVE"),"") | BK6: =IF(AND(AK6="Yes",BE6="LIVE"),COUNTIFS($AK$4:AK6,"Yes",$BE$4:BE6,"LIVE"),"") | BL6: =IF(I6="To Verify",COUNTIF($I$4:I6,"To Verify"),"")
A7: AAD-004 | B7: Aadhaar Centre | C7: Aadhaar Services | D7: Enrolment | E7: Aadhaar Enrolment – Head of Family / Introducer Based | F7: आधार नामांकन – परिवार मुखिया / परिचयकर्ता आधारित | G7: Get Aadhaar Enrolment – Head of Family / Introducer Based done at our Aadhaar Centre. | H7: Special-case Aadhaar enrolment. Availability at this centre is still to be confirmed. | I7: To Verify | J7: =IFERROR(INDEX(AVAILABILITY_MASTER!$C$4:$C$10,MATCH(I7,AVAILABILITY_MASTER!$A$4:$A$10,0)),"To Be Confirmed") -> To Be Confirmed | K7: Depends | L7: To Verify | M7: =IFERROR(INDEX(SERVICE_DOCUMENTS!$S$4:$S$1000,MATCH(A7,SERVICE_DOCUMENTS!$A$4:$A$1000,0))&"","") -> ✓ Customer Presence for Biometrics | N7: =IFERROR(INDEX(SERVICE_DOCUMENTS!$T$4:$T$1000,MATCH(A7,SERVICE_DOCUMENTS!$A$4:$A$1000,0))&"","") -> • Original Documents (To Verify) | O7: Special enrolment cases as permitted by UIDAI. | P7: Step 1 → Contact the shop to confirm whether this special enrolment case can be handled here. Step 2 → If yes, bring the documents the operator asks for. Step 3 → Operator follows the UIDAI procedure for this case. Step 4 → Collect the acknowledgement slip and track the status. | Q7: Depends on Department | R7: To Verify | S7: To Verify | T7: =IF(AND(OR(ISNUMBER(R7),R7="N/A"),OR(ISNUMBER(S7),S7="N/A"),OR(ISNUMBER(R7),ISNUMBER(S7))),N(R7)+N(S7),"To Verify") -> To Verify | U7: To Verify | V7: No | W7: Depends on Service | X7: Offline | Y7: No | AA7: Yes | AB7: Yes | AC7: To Verify | AD7: To Verify | AE7: No | AF7: To Verify | AG7: To Verify | AH7: No | AI7: No | AJ7: No | AK7: No | AL7: Aadhaar Centre | AM7: Enrolment | AN7: =BA7&", "&AZ7 -> Aadhaar Enrolment – Head of Family / Introducer Based, Aadhaar Centre, Devmobile Stores, आधार नामांकन – परिवार मुखिया / परिचयकर्ता आधारित, आधार सेंटर, सेवा | AO7: aadhaar-enrolment-head-of-family-introducer-based | AP7: 🆕 | AQ7: 40 | AR7: Q1: Where can I check the current charges? A1: Charges are confirmed at the shop and may change as per government / bank rules. | AS7: Aadhaar services depend on UIDAI operator authorization. Please confirm with the shop before visiting. | AT7: Fees, documents and processing time are subject to change as per government / bank / portal rules. Final charges are confirmed at the shop before the service starts. | AV7: To Verify | AW7: Only where UIDAI currently permits; confirm with your Registrar | AX7: Aadhaar Enrolment – Head of Family / Introducer Based Service | Devmobile Stores | AY7: Aadhaar Enrolment – Head of Family / Introducer Based (आधार नामांकन – परिवार मुखिया / परिचयकर्ता आधारित) at Devmobile Stores and Common Service Center & Aadhaar Centre. Check required documents, charges and process before you visit. | AZ7: आधार नामांकन – परिवार मुखिया / परिचयकर्ता आधारित, आधार सेंटर, सेवा | BA7: Aadhaar Enrolment – Head of Family / Introducer Based, Aadhaar Centre, Devmobile Stores | BC7: =IFERROR(INDEX(CATEGORY_MASTER!$C$4:$C$30,MATCH(B7,CATEGORY_MASTER!$A$4:$A$30,0)),"") -> 🪪 | BD7: ="/services/"&AO7 -> /services/aadhaar-enrolment-head-of-family-introducer-based | BE7: =IF(AND(AH7="Yes",AG7="Active",I7<>"Not Available"),"LIVE","HIDDEN") -> HIDDEN | BF7: In-person assistance at the shop • Help checking your documents • Receipt / acknowledgement where applicable | BG7: Call Us | BH7: =B7&"|"&COUNTIF($B$4:B7,B7) -> Aadhaar Centre|4 | BI7: =IF(AND(AI7="Yes",BE7="LIVE"),COUNTIFS($AI$4:AI7,"Yes",$BE$4:BE7,"LIVE"),"") | BJ7: =IF(AND(AJ7="Yes",BE7="LIVE"),COUNTIFS($AJ$4:AJ7,"Yes",$BE$4:BE7,"LIVE"),"") | BK7: =IF(AND(AK7="Yes",BE7="LIVE"),COUNTIFS($AK$4:AK7,"Yes",$BE$4:BE7,"LIVE"),"") | BL7: =IF(I7="To Verify",COUNTIF($I$4:I7,"To Verify"),"") -> 1
A8: AAD-005 | B8: Aadhaar Centre | C8: Aadhaar Services | D8: Enrolment | E8: Aadhaar Enrolment – NRI / Foreign Resident | F8: आधार नामांकन – NRI / विदेशी निवासी | G8: Get Aadhaar Enrolment – NRI / Foreign Resident done at our Aadhaar Centre. | H8: Special-case Aadhaar enrolment. Availability at this centre is still to be confirmed. | I8: To Verify | J8: =IFERROR(INDEX(AVAILABILITY_MASTER!$C$4:$C$10,MATCH(I8,AVAILABILITY_MASTER!$A$4:$A$10,0)),"To Be Confirmed") -> To Be Confirmed | K8: Depends | L8: To Verify | M8: =IFERROR(INDEX(SERVICE_DOCUMENTS!$S$4:$S$1000,MATCH(A8,SERVICE_DOCUMENTS!$A$4:$A$1000,0))&"","") -> ✓ Customer Presence for Biometrics | N8: =IFERROR(INDEX(SERVICE_DOCUMENTS!$T$4:$T$1000,MATCH(A8,SERVICE_DOCUMENTS!$A$4:$A$1000,0))&"","") -> • Original Documents (To Verify) | O8: Special enrolment cases as permitted by UIDAI. | P8: Step 1 → Contact the shop to confirm whether this special enrolment case can be handled here. Step 2 → If yes, bring the documents the operator asks for. Step 3 → Operator follows the UIDAI procedure for this case. Step 4 → Collect the acknowledgement slip and track the status. | Q8: Depends on Department | R8: To Verify | S8: To Verify | T8: =IF(AND(OR(ISNUMBER(R8),R8="N/A"),OR(ISNUMBER(S8),S8="N/A"),OR(ISNUMBER(R8),ISNUMBER(S8))),N(R8)+N(S8),"To Verify") -> To Verify | U8: To Verify | V8: No | W8: Depends on Service | X8: Offline | Y8: No | AA8: Yes | AB8: Yes | AC8: To Verify | AD8: To Verify | AE8: No | AF8: To Verify | AG8: To Verify | AH8: No | AI8: No | AJ8: No | AK8: No | AL8: Aadhaar Centre | AM8: Enrolment | AN8: =BA8&", "&AZ8 -> Aadhaar Enrolment – NRI / Foreign Resident, Aadhaar Centre, Devmobile Stores, आधार नामांकन – NRI / विदेशी निवासी, आधार सेंटर, सेवा | AO8: aadhaar-enrolment-nri-foreign-resident | AP8: 🆕 | AQ8: 50 | AR8: Q1: Where can I check the current charges? A1: Charges are confirmed at the shop and may change as per government / bank rules. | AS8: Aadhaar services depend on UIDAI operator authorization. Please confirm with the shop before visiting. | AT8: Fees, documents and processing time are subject to change as per government / bank / portal rules. Final charges are confirmed at the shop before the service starts. | AV8: To Verify | AW8: Usually handled at Aadhaar Seva Kendra; confirm before offering | AX8: Aadhaar Enrolment – NRI / Foreign Resident Service | Devmobile Stores | AY8: Aadhaar Enrolment – NRI / Foreign Resident (आधार नामांकन – NRI / विदेशी निवासी) at Devmobile Stores and Common Service Center & Aadhaar Centre. Check required documents, charges and process before you visit. | AZ8: आधार नामांकन – NRI / विदेशी निवासी, आधार सेंटर, सेवा | BA8: Aadhaar Enrolment – NRI / Foreign Resident, Aadhaar Centre, Devmobile Stores | BC8: =IFERROR(INDEX(CATEGORY_MASTER!$C$4:$C$30,MATCH(B8,CATEGORY_MASTER!$A$4:$A$30,0)),"") -> 🪪 | BD8: ="/services/"&AO8 -> /services/aadhaar-enrolment-nri-foreign-resident | BE8: =IF(AND(AH8="Yes",AG8="Active",I8<>"Not Available"),"LIVE","HIDDEN") -> HIDDEN | BF8: In-person assistance at the shop • Help checking your documents • Receipt / acknowledgement where applicable | BG8: Call Us | BH8: =B8&"|"&COUNTIF($B$4:B8,B8) -> Aadhaar Centre|5 | BI8: =IF(AND(AI8="Yes",BE8="LIVE"),COUNTIFS($AI$4:AI8,"Yes",$BE$4:BE8,"LIVE"),"") | BJ8: =IF(AND(AJ8="Yes",BE8="LIVE"),COUNTIFS($AJ$4:AJ8,"Yes",$BE$4:BE8,"LIVE"),"") | BK8: =IF(AND(AK8="Yes",BE8="LIVE"),COUNTIFS($AK$4:AK8,"Yes",$BE$4:BE8,"LIVE"),"") | BL8: =IF(I8="To Verify",COUNTIF($I$4:I8,"To Verify"),"") -> 2
A9: AAD-006 | B9: Aadhaar Centre | C9: Aadhaar Services | D9: Enrolment | E9: Aadhaar Enrolment – Biometric Exception Case | F9: आधार नामांकन – बायोमेट्रिक अपवाद मामला | G9: Get Aadhaar Enrolment – Biometric Exception Case done at our Aadhaar Centre. | H9: Special-case Aadhaar enrolment. Availability at this centre is still to be confirmed. | I9: To Verify | J9: =IFERROR(INDEX(AVAILABILITY_MASTER!$C$4:$C$10,MATCH(I9,AVAILABILITY_MASTER!$A$4:$A$10,0)),"To Be Confirmed") -> To Be Confirmed | K9: Depends | L9: To Verify | M9: =IFERROR(INDEX(SERVICE_DOCUMENTS!$S$4:$S$1000,MATCH(A9,SERVICE_DOCUMENTS!$A$4:$A$1000,0))&"","") -> ✓ Customer Presence for Biometrics | N9: =IFERROR(INDEX(SERVICE_DOCUMENTS!$T$4:$T$1000,MATCH(A9,SERVICE_DOCUMENTS!$A$4:$A$1000,0))&"","") -> • Original Documents (To Verify) | O9: Special enrolment cases as permitted by UIDAI. | P9: Step 1 → Contact the shop to confirm whether this special enrolment case can be handled here. Step 2 → If yes, bring the documents the operator asks for. Step 3 → Operator follows the UIDAI procedure for this case. Step 4 → Collect the acknowledgement slip and track the status. | Q9: Depends on Department | R9: To Verify | S9: To Verify | T9: =IF(AND(OR(ISNUMBER(R9),R9="N/A"),OR(ISNUMBER(S9),S9="N/A"),OR(ISNUMBER(R9),ISNUMBER(S9))),N(R9)+N(S9),"To Verify") -> To Verify | U9: To Verify | V9: No | W9: Depends on Service | X9: Offline | Y9: No | AA9: Yes | AB9: Yes | AC9: To Verify | AD9: To Verify | AE9: No | AF9: To Verify | AG9: To Verify | AH9: No | AI9: No | AJ9: No | AK9: No | AL9: Aadhaar Centre | AM9: Enrolment | AN9: =BA9&", "&AZ9 -> Aadhaar Enrolment – Biometric Exception Case, Aadhaar Centre, Devmobile Stores, आधार नामांकन – बायोमेट्रिक अपवाद मामला, आधार सेंटर, सेवा | AO9: aadhaar-enrolment-biometric-exception-case | AP9: 🆕 | AQ9: 60 | AR9: Q1: Where can I check the current charges? A1: Charges are confirmed at the shop and may change as per government / bank rules. | AS9: Aadhaar services depend on UIDAI operator authorization. Please confirm with the shop before visiting. | AT9: Fees, documents and processing time are subject to change as per government / bank / portal rules. Final charges are confirmed at the shop before the service starts. | AV9: To Verify | AW9: Special procedure; confirm with Registrar / UIDAI | AX9: Aadhaar Enrolment – Biometric Exception Case Service | Devmobile Stores | AY9: Aadhaar Enrolment – Biometric Exception Case (आधार नामांकन – बायोमेट्रिक अपवाद मामला) at Devmobile Stores and Common Service Center & Aadhaar Centre. Check required documents, charges and process before you visit. | AZ9: आधार नामांकन – बायोमेट्रिक अपवाद मामला, आधार सेंटर, सेवा | BA9: Aadhaar Enrolment – Biometric Exception Case, Aadhaar Centre, Devmobile Stores | BC9: =IFERROR(INDEX(CATEGORY_MASTER!$C$4:$C$30,MATCH(B9,CATEGORY_MASTER!$A$4:$A$30,0)),"") -> 🪪 | BD9: ="/services/"&AO9 -> /services/aadhaar-enrolment-biometric-exception-case | BE9: =IF(AND(AH9="Yes",AG9="Active",I9<>"Not Available"),"LIVE","HIDDEN") -> HIDDEN | BF9: In-person assistance at the shop • Help checking your documents • Receipt / acknowledgement where applicable | BG9: Call Us | BH9: =B9&"|"&COUNTIF($B$4:B9,B9) -> Aadhaar Centre|6 | BI9: =IF(AND(AI9="Yes",BE9="LIVE"),COUNTIFS($AI$4:AI9,"Yes",$BE$4:BE9,"LIVE"),"") | BJ9: =IF(AND(AJ9="Yes",BE9="LIVE"),COUNTIFS($AJ$4:AJ9,"Yes",$BE$4:BE9,"LIVE"),"") | BK9: =IF(AND(AK9="Yes",BE9="LIVE"),COUNTIFS($AK$4:AK9,"Yes",$BE$4:BE9,"LIVE"),"") | BL9: =IF(I9="To Verify",COUNTIF($I$4:I9,"To Verify"),"") -> 3
A10: AAD-007 | B10: Aadhaar Centre | C10: Aadhaar Services | D10: Demographic Update | E10: Aadhaar Name Update | F10: आधार नाम अपडेट | G10: Get Aadhaar Name Update done at our Aadhaar Centre. | H10: Update or correct the name recorded in your Aadhaar through the Aadhaar Centre. | I10: Available | J10: =IFERROR(INDEX(AVAILABILITY_MASTER!$C$4:$C$10,MATCH(I10,AVAILABILITY_MASTER!$A$4:$A$10,0)),"To Be Confirmed") -> Available | K10: Yes | L10: To Verify | M10: =IFERROR(INDEX(SERVICE_DOCUMENTS!$S$4:$S$1000,MATCH(A10,SERVICE_DOCUMENTS!$A$4:$A$1000,0))&"","") -> ✓ Aadhaar Card ✓ Proof of Name | N10: =IFERROR(INDEX(SERVICE_DOCUMENTS!$T$4:$T$1000,MATCH(A10,SERVICE_DOCUMENTS!$A$4:$A$1000,0))&"","") | O10: Aadhaar holders whose details need correction, subject to UIDAI update limits. | P10: Step 1 → Bring your Aadhaar card and proof of name (originals). Step 2 → Operator checks your current Aadhaar details and the document for the name change. Step 3 → Aadhaar holder gives fingerprint / biometric authentication at the centre. Step 4 → New name details are entered and shown to you for checking before submission. Step 5 → Pay the charge and collect the acknowledgement slip (URN) to track the update. | Q10: Depends on Department | R10: To Verify | S10: To Verify | T10: =IF(AND(OR(ISNUMBER(R10),R10="N/A"),OR(ISNUMBER(S10),S10="N/A"),OR(ISNUMBER(R10),ISNUMBER(S10))),N(R10)+N(S10),"To Verify") -> To Verify | U10: To Verify | V10: No | W10: Depends on Service | X10: Offline | Y10: No | AA10: Yes | AB10: Yes | AC10: To Verify | AD10: To Verify | AE10: No | AF10: To Verify | AG10: Active | AH10: Yes | AI10: No | AJ10: No | AK10: No | AL10: Aadhaar Centre | AM10: Demographic Update | AN10: =BA10&", "&AZ10 -> Aadhaar Name Update, Aadhaar Centre, Devmobile Stores, आधार नाम अपडेट, आधार सेंटर, सेवा | AO10: aadhaar-name-update | AP10: ✏️ | AQ10: 70 | AR10: Q1: Do I need to come in person? A1: Yes, the Aadhaar holder normally gives biometric authentication at the centre. Q2: Is there a limit on changes? A2: UIDAI limits some updates. Ask the operator for the current rule. | AS10: Aadhaar services depend on UIDAI operator authorization. Please confirm with the shop before visiting. | AT10: Fees, documents and processing time are subject to change as per government / bank / portal rules. Final charges are confirmed at the shop before the service starts. | AV10: To Verify | AW10: UIDAI limits how many times name can be changed; verify current rule | Set to Available as per owner's example; authorization still To Verify. | AX10: Aadhaar Name Update Service | Devmobile Stores | AY10: Aadhaar Name Update (आधार नाम अपडेट) at Devmobile Stores and Common Service Center & Aadhaar Centre. Check required documents, charges and process before you visit. | AZ10: आधार नाम अपडेट, आधार सेंटर, सेवा | BA10: Aadhaar Name Update, Aadhaar Centre, Devmobile Stores | BC10: =IFERROR(INDEX(CATEGORY_MASTER!$C$4:$C$30,MATCH(B10,CATEGORY_MASTER!$A$4:$A$30,0)),"") -> 🪪 | BD10: ="/services/"&AO10 -> /services/aadhaar-name-update | BE10: =IF(AND(AH10="Yes",AG10="Active",I10<>"Not Available"),"LIVE","HIDDEN") -> LIVE | BF10: Correct Aadhaar details • Biometric-verified update • Acknowledgement slip | BG10: Check Documents | BH10: =B10&"|"&COUNTIF($B$4:B10,B10) -> Aadhaar Centre|7 | BI10: =IF(AND(AI10="Yes",BE10="LIVE"),COUNTIFS($AI$4:AI10,"Yes",$BE$4:BE10,"LIVE"),"") | BJ10: =IF(AND(AJ10="Yes",BE10="LIVE"),COUNTIFS($AJ$4:AJ10,"Yes",$BE$4:BE10,"LIVE"),"") | BK10: =IF(AND(AK10="Yes",BE10="LIVE"),COUNTIFS($AK$4:AK10,"Yes",$BE$4:BE10,"LIVE"),"") | BL10: =IF(I10="To Verify",COUNTIF($I$4:I10,"To Verify"),"")
A11: AAD-008 | B11: Aadhaar Centre | C11: Aadhaar Services | D11: Demographic Update | E11: Aadhaar Date of Birth Update | F11: आधार जन्म तिथि अपडेट | G11: Get Aadhaar Date of Birth Update done at our Aadhaar Centre. | H11: Update or correct the date of birth recorded in your Aadhaar through the Aadhaar Centre. | I11: Available | J11: =IFERROR(INDEX(AVAILABILITY_MASTER!$C$4:$C$10,MATCH(I11,AVAILABILITY_MASTER!$A$4:$A$10,0)),"To Be Confirmed") -> Available | K11: Yes | L11: To Verify | M11: =IFERROR(INDEX(SERVICE_DOCUMENTS!$S$4:$S$1000,MATCH(A11,SERVICE_DOCUMENTS!$A$4:$A$1000,0))&"","") -> ✓ Aadhaar Card ✓ Date of Birth Proof | N11: =IFERROR(INDEX(SERVICE_DOCUMENTS!$T$4:$T$1000,MATCH(A11,SERVICE_DOCUMENTS!$A$4:$A$1000,0))&"","") | O11: Aadhaar holders whose details need correction, subject to UIDAI update limits. | P11: Step 1 → Bring your Aadhaar card and date-of-birth proof (originals). Step 2 → Operator checks your current Aadhaar details and the document for the date of birth change. Step 3 → Aadhaar holder gives fingerprint / biometric authentication at the centre. Step 4 → New date of birth details are entered and shown to you for checking before submission. Step 5 → Pay the charge and collect the acknowledgement slip (URN) to track the update. | Q11: Depends on Department | R11: To Verify | S11: To Verify | T11: =IF(AND(OR(ISNUMBER(R11),R11="N/A"),OR(ISNUMBER(S11),S11="N/A"),OR(ISNUMBER(R11),ISNUMBER(S11))),N(R11)+N(S11),"To Verify") -> To Verify | U11: To Verify | V11: No | W11: Depends on Service | X11: Offline | Y11: No | AA11: Yes | AB11: Yes | AC11: To Verify | AD11: To Verify | AE11: No | AF11: To Verify | AG11: Active | AH11: Yes | AI11: No | AJ11: No | AK11: No | AL11: Aadhaar Centre | AM11: Demographic Update | AN11: =BA11&", "&AZ11 -> Aadhaar Date of Birth Update, Aadhaar Centre, Devmobile Stores, आधार जन्म तिथि अपडेट, आधार सेंटर, सेवा | AO11: aadhaar-date-of-birth-update | AP11: ✏️ | AQ11: 80 | AR11: Q1: Do I need to come in person? A1: Yes, the Aadhaar holder normally gives biometric authentication at the centre. Q2: Is there a limit on changes? A2: UIDAI limits some updates. Ask the operator for the current rule. | AS11: Aadhaar services depend on UIDAI operator authorization. Please confirm with the shop before visiting. | AT11: Fees, documents and processing time are subject to change as per government / bank / portal rules. Final charges are confirmed at the shop before the service starts. | AV11: To Verify | AW11: UIDAI limits DoB changes; supporting DoB proof needed; verify current rule | Set to Available as per owner's example; authorization still To Verify. | AX11: Aadhaar Date of Birth Update Service | Devmobile Stores | AY11: Aadhaar Date of Birth Update (आधार जन्म तिथि अपडेट) at Devmobile Stores and Common Service Center & Aadhaar Centre. Check required documents, charges and process before you visit. | AZ11: आधार जन्म तिथि अपडेट, आधार सेंटर, सेवा | BA11: Aadhaar Date of Birth Update, Aadhaar Centre, Devmobile Stores | BC11: =IFERROR(INDEX(CATEGORY_MASTER!$C$4:$C$30,MATCH(B11,CATEGORY_MASTER!$A$4:$A$30,0)),"") -> 🪪 | BD11: ="/services/"&AO11 -> /services/aadhaar-date-of-birth-update | BE11: =IF(AND(AH11="Yes",AG11="Active",I11<>"Not Available"),"LIVE","HIDDEN") -> LIVE | BF11: Correct Aadhaar details • Biometric-verified update • Acknowledgement slip | BG11: Check Documents | BH11: =B11&"|"&COUNTIF($B$4:B11,B11) -> Aadhaar Centre|8 | BI11: =IF(AND(AI11="Yes",BE11="LIVE"),COUNTIFS($AI$4:AI11,"Yes",$BE$4:BE11,"LIVE"),"") | BJ11: =IF(AND(AJ11="Yes",BE11="LIVE"),COUNTIFS($AJ$4:AJ11,"Yes",$BE$4:BE11,"LIVE"),"") | BK11: =IF(AND(AK11="Yes",BE11="LIVE"),COUNTIFS($AK$4:AK11,"Yes",$BE$4:BE11,"LIVE"),"") | BL11: =IF(I11="To Verify",COUNTIF($I$4:I11,"To Verify"),"")
A12: AAD-009 | B12: Aadhaar Centre | C12: Aadhaar Services | D12: Demographic Update | E12: Aadhaar Gender Update | F12: आधार लिंग अपडेट | G12: Get Aadhaar Gender Update done at our Aadhaar Centre. | H12: Update or correct the gender recorded in your Aadhaar through the Aadhaar Centre. | I12: Available | J12: =IFERROR(INDEX(AVAILABILITY_MASTER!$C$4:$C$10,MATCH(I12,AVAILABILITY_MASTER!$A$4:$A$10,0)),"To Be Confirmed") -> Available | K12: Yes | L12: To Verify | M12: =IFERROR(INDEX(SERVICE_DOCUMENTS!$S$4:$S$1000,MATCH(A12,SERVICE_DOCUMENTS!$A$4:$A$1000,0))&"","") -> ✓ Aadhaar Card | N12: =IFERROR(INDEX(SERVICE_DOCUMENTS!$T$4:$T$1000,MATCH(A12,SERVICE_DOCUMENTS!$A$4:$A$1000,0))&"","") -> • Identity Proof (To Verify) | O12: Aadhaar holders whose details need correction, subject to UIDAI update limits. | P12: Step 1 → Bring your Aadhaar card and identity proof (originals). Step 2 → Operator checks your current Aadhaar details and the document for the gender change. Step 3 → Aadhaar holder gives fingerprint / biometric authentication at the centre. Step 4 → New gender details are entered and shown to you for checking before submission. Step 5 → Pay the charge and collect the acknowledgement slip (URN) to track the update. | Q12: Depends on Department | R12: To Verify | S12: To Verify | T12: =IF(AND(OR(ISNUMBER(R12),R12="N/A"),OR(ISNUMBER(S12),S12="N/A"),OR(ISNUMBER(R12),ISNUMBER(S12))),N(R12)+N(S12),"To Verify") -> To Verify | U12: To Verify | V12: No | W12: Depends on Service | X12: Offline | Y12: No | AA12: Yes | AB12: Yes | AC12: To Verify | AD12: To Verify | AE12: No | AF12: To Verify | AG12: Active | AH12: Yes | AI12: No | AJ12: No | AK12: No | AL12: Aadhaar Centre | AM12: Demographic Update | AN12: =BA12&", "&AZ12 -> Aadhaar Gender Update, Aadhaar Centre, Devmobile Stores, आधार लिंग अपडेट, आधार सेंटर, सेवा | AO12: aadhaar-gender-update | AP12: ✏️ | AQ12: 90 | AR12: Q1: Do I need to come in person? A1: Yes, the Aadhaar holder normally gives biometric authentication at the centre. Q2: Is there a limit on changes? A2: UIDAI limits some updates. Ask the operator for the current rule. | AS12: Aadhaar services depend on UIDAI operator authorization. Please confirm with the shop before visiting. | AT12: Fees, documents and processing time are subject to change as per government / bank / portal rules. Final charges are confirmed at the shop before the service starts. | AV12: To Verify | AW12: UIDAI limits gender changes; verify current rule | Set to Available as per owner's example; authorization still To Verify. | AX12: Aadhaar Gender Update Service | Devmobile Stores | AY12: Aadhaar Gender Update (आधार लिंग अपडेट) at Devmobile Stores and Common Service Center & Aadhaar Centre. Check required documents, charges and process before you visit. | AZ12: आधार लिंग अपडेट, आधार सेंटर, सेवा | BA12: Aadhaar Gender Update, Aadhaar Centre, Devmobile Stores | BC12: =IFERROR(INDEX(CATEGORY_MASTER!$C$4:$C$30,MATCH(B12,CATEGORY_MASTER!$A$4:$A$30,0)),"") -> 🪪 | BD12: ="/services/"&AO12 -> /services/aadhaar-gender-update | BE12: =IF(AND(AH12="Yes",AG12="Active",I12<>"Not Available"),"LIVE","HIDDEN") -> LIVE | BF12: Correct Aadhaar details • Biometric-verified update • Acknowledgement slip | BG12: Check Documents | BH12: =B12&"|"&COUNTIF($B$4:B12,B12) -> Aadhaar Centre|9 | BI12: =IF(AND(AI12="Yes",BE12="LIVE"),COUNTIFS($AI$4:AI12,"Yes",$BE$4:BE12,"LIVE"),"") | BJ12: =IF(AND(AJ12="Yes",BE12="LIVE"),COUNTIFS($AJ$4:AJ12,"Yes",$BE$4:BE12,"LIVE"),"") | BK12: =IF(AND(AK12="Yes",BE12="LIVE"),COUNTIFS($AK$4:AK12,"Yes",$BE$4:BE12,"LIVE"),"") | BL12: =IF(I12="To Verify",COUNTIF($I$4:I12,"To Verify"),"")
A13: AAD-010 | B13: Aadhaar Centre | C13: Aadhaar Services | D13: Demographic Update | E13: Aadhaar Address Update (with Document) | F13: आधार पता अपडेट (दस्तावेज़ के साथ) | G13: Get Aadhaar Address Update (with Document) done at our Aadhaar Centre. | H13: Update or correct the address recorded in your Aadhaar through the Aadhaar Centre. | I13: Available | J13: =IFERROR(INDEX(AVAILABILITY_MASTER!$C$4:$C$10,MATCH(I13,AVAILABILITY_MASTER!$A$4:$A$10,0)),"To Be Confirmed") -> Available | K13: Yes | L13: To Verify | M13: =IFERROR(INDEX(SERVICE_DOCUMENTS!$S$4:$S$1000,MATCH(A13,SERVICE_DOCUMENTS!$A$4:$A$1000,0))&"","") -> ✓ Aadhaar Card ✓ Address Proof | N13: =IFERROR(INDEX(SERVICE_DOCUMENTS!$T$4:$T$1000,MATCH(A13,SERVICE_DOCUMENTS!$A$4:$A$1000,0))&"","") | O13: Aadhaar holders whose details need correction, subject to UIDAI update limits. | P13: Step 1 → Bring your Aadhaar card and address proof (originals). Step 2 → Operator checks your current Aadhaar details and the document for the address change. Step 3 → Aadhaar holder gives fingerprint / biometric authentication at the centre. Step 4 → New address details are entered and shown to you for checking before submission. Step 5 → Pay the charge and collect the acknowledgement slip (URN) to track the update. | Q13: Depends on Department | R13: To Verify | S13: To Verify | T13: =IF(AND(OR(ISNUMBER(R13),R13="N/A"),OR(ISNUMBER(S13),S13="N/A"),OR(ISNUMBER(R13),ISNUMBER(S13))),N(R13)+N(S13),"To Verify") -> To Verify | U13: To Verify | V13: No | W13: Depends on Service | X13: Offline | Y13: No | AA13: Yes | AB13: Yes | AC13: To Verify | AD13: To Verify | AE13: No | AF13: To Verify | AG13: Active | AH13: Yes | AI13: No | AJ13: No | AK13: No | AL13: Aadhaar Centre | AM13: Demographic Update | AN13: =BA13&", "&AZ13 -> Aadhaar Address Update (with Document), Aadhaar Centre, Devmobile Stores, आधार पता अपडेट (दस्तावेज़ के साथ), आधार सेंटर, सेवा | AO13: aadhaar-address-update-with-document | AP13: ✏️ | AQ13: 100 | AR13: Q1: Do I need to come in person? A1: Yes, the Aadhaar holder normally gives biometric authentication at the centre. Q2: Is there a limit on changes? A2: UIDAI limits some updates. Ask the operator for the current rule. | AS13: Aadhaar services depend on UIDAI operator authorization. Please confirm with the shop before visiting. | AT13: Fees, documents and processing time are subject to change as per government / bank / portal rules. Final charges are confirmed at the shop before the service starts. | AV13: To Verify | AW13: Valid address proof as per current UIDAI list | Set to Available as per owner's example; authorization still To Verify. | AX13: Aadhaar Address Update (with Document) Service | Devmobile Stores | AY13: Aadhaar Address Update (with Document) (आधार पता अपडेट (दस्तावेज़ के साथ)) at Devmobile Stores and Common Service Center & Aadhaar Centre. Check required documents, charges and process before you visit. | AZ13: आधार पता अपडेट (दस्तावेज़ के साथ), आधार सेंटर, सेवा | BA13: Aadhaar Address Update (with Document), Aadhaar Centre, Devmobile Stores | BC13: =IFERROR(INDEX(CATEGORY_MASTER!$C$4:$C$30,MATCH(B13,CATEGORY_MASTER!$A$4:$A$30,0)),"") -> 🪪 | BD13: ="/services/"&AO13 -> /services/aadhaar-address-update-with-document | BE13: =IF(AND(AH13="Yes",AG13="Active",I13<>"Not Available"),"LIVE","HIDDEN") -> LIVE | BF13: Correct Aadhaar details • Biometric-verified update • Acknowledgement slip | BG13: Check Documents | BH13: =B13&"|"&COUNTIF($B$4:B13,B13) -> Aadhaar Centre|10 | BI13: =IF(AND(AI13="Yes",BE13="LIVE"),COUNTIFS($AI$4:AI13,"Yes",$BE$4:BE13,"LIVE"),"") | BJ13: =IF(AND(AJ13="Yes",BE13="LIVE"),COUNTIFS($AJ$4:AJ13,"Yes",$BE$4:BE13,"LIVE"),"") | BK13: =IF(AND(AK13="Yes",BE13="LIVE"),COUNTIFS($AK$4:AK13,"Yes",$BE$4:BE13,"LIVE"),"") | BL13: =IF(I13="To Verify",COUNTIF($I$4:I13,"To Verify"),"")
A14: AAD-011 | B14: Aadhaar Centre | C14: Aadhaar Services | D14: Demographic Update | E14: Aadhaar Address Update – Online (SSUP) Assistance | F14: आधार पता अपडेट – ऑनलाइन (SSUP) सहायता | G14: Get Aadhaar Address Update – Online (SSUP) Assistance done at our Aadhaar Centre. | H14: Assistance to update Aadhaar address online through the UIDAI portal. | I14: Portal Dependent | J14: =IFERROR(INDEX(AVAILABILITY_MASTER!$C$4:$C$10,MATCH(I14,AVAILABILITY_MASTER!$A$4:$A$10,0)),"To Be Confirmed") -> Depends on Portal – Confirm at Shop | K14: Depends | L14: Portal Dependent | M14: =IFERROR(INDEX(SERVICE_DOCUMENTS!$S$4:$S$1000,MATCH(A14,SERVICE_DOCUMENTS!$A$4:$A$1000,0))&"","") -> ✓ Aadhaar Card ✓ Aadhaar-Linked Mobile Number ✓ Address Proof | N14: =IFERROR(INDEX(SERVICE_DOCUMENTS!$T$4:$T$1000,MATCH(A14,SERVICE_DOCUMENTS!$A$4:$A$1000,0))&"","") | O14: Aadhaar holders with a linked mobile number. | P14: Step 1 → Bring your Aadhaar number, the phone linked to Aadhaar and your address proof. Step 2 → Operator opens the UIDAI Self Service Update Portal and logs in with OTP. Step 3 → New address is entered and the address-proof file is uploaded. Step 4 → Payment is made online and an update request number (URN) is generated. Step 5 → Track the update with the URN. | Q14: Depends on Department | R14: To Verify | S14: To Verify | T14: =IF(AND(OR(ISNUMBER(R14),R14="N/A"),OR(ISNUMBER(S14),S14="N/A"),OR(ISNUMBER(R14),ISNUMBER(S14))),N(R14)+N(S14),"To Verify") -> To Verify | U14: To Verify | V14: No | W14: Depends on Service | X14: Online | Y14: Yes | Z14: UIDAI Self Service Update Portal (SSUP) | AA14: Depends | AB14: No | AC14: To Verify | AD14: To Verify | AE14: No | AF14: No | AG14: To Verify | AH14: No | AI14: No | AJ14: No | AK14: No | AL14: Aadhaar Centre | AM14: Demographic Update | AN14: =BA14&", "&AZ14 -> Aadhaar Address Update – Online (SSUP) Assistance, Aadhaar Centre, Devmobile Stores, आधार पता अपडेट – ऑनलाइन (SSUP) सहायता, आधार सेंटर, सेवा | AO14: aadhaar-address-update-online-ssup-assistance | AP14: ✏️ | AQ14: 110 | AR14: Q1: Where can I check the current charges? A1: Charges are confirmed at the shop and may change as per government / bank rules. | AS14: Needs a mobile number already linked to Aadhaar for OTP. | AT14: Fees, documents and processing time are subject to change as per government / bank / portal rules. Final charges are confirmed at the shop before the service starts. | AV14: To Verify | AW14: Needs mobile number linked to Aadhaar for OTP | AX14: Aadhaar Address Update – Online (SSUP) Assistance Service | Devmobile Stores | AY14: Aadhaar Address Update – Online (SSUP) Assistance (आधार पता अपडेट – ऑनलाइन (SSUP) सहायता) at Devmobile Stores and Common Service Center & Aadhaar Centre. Check required documents, charges and process before you visit. | AZ14: आधार पता अपडेट – ऑनलाइन (SSUP) सहायता, आधार सेंटर, सेवा | BA14: Aadhaar Address Update – Online (SSUP) Assistance, Aadhaar Centre, Devmobile Stores | BC14: =IFERROR(INDEX(CATEGORY_MASTER!$C$4:$C$30,MATCH(B14,CATEGORY_MASTER!$A$4:$A$30,0)),"") -> 🪪 | BD14: ="/services/"&AO14 -> /services/aadhaar-address-update-online-ssup-assistance | BE14: =IF(AND(AH14="Yes",AG14="Active",I14<>"Not Available"),"LIVE","HIDDEN") -> HIDDEN | BF14: In-person assistance at the shop • Help checking your documents • Receipt / acknowledgement where applicable | BG14: Book Service | BH14: =B14&"|"&COUNTIF($B$4:B14,B14) -> Aadhaar Centre|11 | BI14: =IF(AND(AI14="Yes",BE14="LIVE"),COUNTIFS($AI$4:AI14,"Yes",$BE$4:BE14,"LIVE"),"") | BJ14: =IF(AND(AJ14="Yes",BE14="LIVE"),COUNTIFS($AJ$4:AJ14,"Yes",$BE$4:BE14,"LIVE"),"") | BK14: =IF(AND(AK14="Yes",BE14="LIVE"),COUNTIFS($AK$4:AK14,"Yes",$BE$4:BE14,"LIVE"),"") | BL14: =IF(I14="To Verify",COUNTIF($I$4:I14,"To Verify"),"")
A15: AAD-012 | B15: Aadhaar Centre | C15: Aadhaar Services | D15: Demographic Update | E15: Aadhaar Mobile Number Update | F15: आधार मोबाइल नंबर अपडेट | G15: Get Aadhaar Mobile Number Update done at our Aadhaar Centre. | H15: Update or correct the mobile number recorded in your Aadhaar through the Aadhaar Centre. | I15: Available | J15: =IFERROR(INDEX(AVAILABILITY_MASTER!$C$4:$C$10,MATCH(I15,AVAILABILITY_MASTER!$A$4:$A$10,0)),"To Be Confirmed") -> Available | K15: Yes | L15: To Verify | M15: =IFERROR(INDEX(SERVICE_DOCUMENTS!$S$4:$S$1000,MATCH(A15,SERVICE_DOCUMENTS!$A$4:$A$1000,0))&"","") -> ✓ Aadhaar Card ✓ Active Mobile Number | N15: =IFERROR(INDEX(SERVICE_DOCUMENTS!$T$4:$T$1000,MATCH(A15,SERVICE_DOCUMENTS!$A$4:$A$1000,0))&"","") | O15: Aadhaar holders whose details need correction, subject to UIDAI update limits. | P15: Step 1 → Bring your Aadhaar card and the new mobile number (originals). Step 2 → Operator checks your current Aadhaar details and the document for the mobile number change. Step 3 → Aadhaar holder gives fingerprint / biometric authentication at the centre. Step 4 → New mobile number details are entered and shown to you for checking before submission. Step 5 → Pay the charge and collect the acknowledgement slip (URN) to track the update. | Q15: Depends on Department | R15: To Verify | S15: To Verify | T15: =IF(AND(OR(ISNUMBER(R15),R15="N/A"),OR(ISNUMBER(S15),S15="N/A"),OR(ISNUMBER(R15),ISNUMBER(S15))),N(R15)+N(S15),"To Verify") -> To Verify | U15: To Verify | V15: No | W15: Depends on Service | X15: Offline | Y15: No | AA15: Yes | AB15: Yes | AC15: To Verify | AD15: To Verify | AE15: No | AF15: To Verify | AG15: Active | AH15: Yes | AI15: No | AJ15: No | AK15: No | AL15: Aadhaar Centre | AM15: Demographic Update | AN15: =BA15&", "&AZ15 -> Aadhaar Mobile Number Update, Aadhaar Centre, Devmobile Stores, आधार मोबाइल नंबर अपडेट, आधार सेंटर, सेवा | AO15: aadhaar-mobile-number-update | AP15: ✏️ | AQ15: 120 | AR15: Q1: Do I need to come in person? A1: Yes, the Aadhaar holder normally gives biometric authentication at the centre. Q2: Is there a limit on changes? A2: UIDAI limits some updates. Ask the operator for the current rule. | AS15: Aadhaar services depend on UIDAI operator authorization. Please confirm with the shop before visiting. | AT15: Fees, documents and processing time are subject to change as per government / bank / portal rules. Final charges are confirmed at the shop before the service starts. | AV15: To Verify | AW15: Biometric authentication of resident required at centre | Set to Available as per owner's example; authorization still To Verify. | AX15: Aadhaar Mobile Number Update Service | Devmobile Stores | AY15: Aadhaar Mobile Number Update (आधार मोबाइल नंबर अपडेट) at Devmobile Stores and Common Service Center & Aadhaar Centre. Check required documents, charges and process before you visit. | AZ15: आधार मोबाइल नंबर अपडेट, आधार सेंटर, सेवा | BA15: Aadhaar Mobile Number Update, Aadhaar Centre, Devmobile Stores | BC15: =IFERROR(INDEX(CATEGORY_MASTER!$C$4:$C$30,MATCH(B15,CATEGORY_MASTER!$A$4:$A$30,0)),"") -> 🪪 | BD15: ="/services/"&AO15 -> /services/aadhaar-mobile-number-update | BE15: =IF(AND(AH15="Yes",AG15="Active",I15<>"Not Available"),"LIVE","HIDDEN") -> LIVE | BF15: Correct Aadhaar details • Biometric-verified update • Acknowledgement slip | BG15: Check Documents | BH15: =B15&"|"&COUNTIF($B$4:B15,B15) -> Aadhaar Centre|12 | BI15: =IF(AND(AI15="Yes",BE15="LIVE"),COUNTIFS($AI$4:AI15,"Yes",$BE$4:BE15,"LIVE"),"") | BJ15: =IF(AND(AJ15="Yes",BE15="LIVE"),COUNTIFS($AJ$4:AJ15,"Yes",$BE$4:BE15,"LIVE"),"") | BK15: =IF(AND(AK15="Yes",BE15="LIVE"),COUNTIFS($AK$4:AK15,"Yes",$BE$4:BE15,"LIVE"),"") | BL15: =IF(I15="To Verify",COUNTIF($I$4:I15,"To Verify"),"")
A16: AAD-013 | B16: Aadhaar Centre | C16: Aadhaar Services | D16: Demographic Update | E16: Aadhaar Email ID Update | F16: आधार ईमेल आईडी अपडेट | G16: Get Aadhaar Email ID Update done at our Aadhaar Centre. | H16: Update or correct the email id recorded in your Aadhaar through the Aadhaar Centre. | I16: Available | J16: =IFERROR(INDEX(AVAILABILITY_MASTER!$C$4:$C$10,MATCH(I16,AVAILABILITY_MASTER!$A$4:$A$10,0)),"To Be Confirmed") -> Available | K16: Yes | L16: To Verify | M16: =IFERROR(INDEX(SERVICE_DOCUMENTS!$S$4:$S$1000,MATCH(A16,SERVICE_DOCUMENTS!$A$4:$A$1000,0))&"","") -> ✓ Aadhaar Card ✓ Email ID | N16: =IFERROR(INDEX(SERVICE_DOCUMENTS!$T$4:$T$1000,MATCH(A16,SERVICE_DOCUMENTS!$A$4:$A$1000,0))&"","") | O16: Aadhaar holders whose details need correction, subject to UIDAI update limits. | P16: Step 1 → Bring your Aadhaar card and the email address (originals). Step 2 → Operator checks your current Aadhaar details and the document for the email id change. Step 3 → Aadhaar holder gives fingerprint / biometric authentication at the centre. Step 4 → New email id details are entered and shown to you for checking before submission. Step 5 → Pay the charge and collect the acknowledgement slip (URN) to track the update. | Q16: Depends on Department | R16: To Verify | S16: To Verify | T16: =IF(AND(OR(ISNUMBER(R16),R16="N/A"),OR(ISNUMBER(S16),S16="N/A"),OR(ISNUMBER(R16),ISNUMBER(S16))),N(R16)+N(S16),"To Verify") -> To Verify | U16: To Verify | V16: No | W16: Depends on Service | X16: Offline | Y16: No | AA16: Yes | AB16: Yes | AC16: To Verify | AD16: To Verify | AE16: No | AF16: To Verify | AG16: Active | AH16: Yes | AI16: No | AJ16: No | AK16: No | AL16: Aadhaar Centre | AM16: Demographic Update | AN16: =BA16&", "&AZ16 -> Aadhaar Email ID Update, Aadhaar Centre, Devmobile Stores, आधार ईमेल आईडी अपडेट, आधार सेंटर, सेवा | AO16: aadhaar-email-id-update | AP16: ✏️ | AQ16: 130 | AR16: Q1: Do I need to come in person? A1: Yes, the Aadhaar holder normally gives biometric authentication at the centre. Q2: Is there a limit on changes? A2: UIDAI limits some updates. Ask the operator for the current rule. | AS16: Aadhaar services depend on UIDAI operator authorization. Please confirm with the shop before visiting. | AT16: Fees, documents and processing time are subject to change as per government / bank / portal rules. Final charges are confirmed at the shop before the service starts. | AV16: To Verify | AW16: Set to Available as per owner's example; authorization still To Verify. | AX16: Aadhaar Email ID Update Service | Devmobile Stores | AY16: Aadhaar Email ID Update (आधार ईमेल आईडी अपडेट) at Devmobile Stores and Common Service Center & Aadhaar Centre. Check required documents, charges and process before you visit. | AZ16: आधार ईमेल आईडी अपडेट, आधार सेंटर, सेवा | BA16: Aadhaar Email ID Update, Aadhaar Centre, Devmobile Stores | BC16: =IFERROR(INDEX(CATEGORY_MASTER!$C$4:$C$30,MATCH(B16,CATEGORY_MASTER!$A$4:$A$30,0)),"") -> 🪪 | BD16: ="/services/"&AO16 -> /services/aadhaar-email-id-update | BE16: =IF(AND(AH16="Yes",AG16="Active",I16<>"Not Available"),"LIVE","HIDDEN") -> LIVE | BF16: Correct Aadhaar details • Biometric-verified update • Acknowledgement slip | BG16: Check Documents | BH16: =B16&"|"&COUNTIF($B$4:B16,B16) -> Aadhaar Centre|13 | BI16: =IF(AND(AI16="Yes",BE16="LIVE"),COUNTIFS($AI$4:AI16,"Yes",$BE$4:BE16,"LIVE"),"") | BJ16: =IF(AND(AJ16="Yes",BE16="LIVE"),COUNTIFS($AJ$4:AJ16,"Yes",$BE$4:BE16,"LIVE"),"") | BK16: =IF(AND(AK16="Yes",BE16="LIVE"),COUNTIFS($AK$4:AK16,"Yes",$BE$4:BE16,"LIVE"),"") | BL16: =IF(I16="To Verify",COUNTIF($I$4:I16,"To Verify"),"")
A17: AAD-014 | B17: Aadhaar Centre | C17: Aadhaar Services | D17: Demographic Update | E17: Aadhaar Relationship / Head of Family Detail Update | F17: आधार संबंध / परिवार मुखिया विवरण अपडेट | G17: Get Aadhaar Relationship / Head of Family Detail Update done at our Aadhaar Centre. | H17: Update or correct the relationship / head of family detail recorded in your Aadhaar through the Aadhaar Centre. | I17: To Verify | J17: =IFERROR(INDEX(AVAILABILITY_MASTER!$C$4:$C$10,MATCH(I17,AVAILABILITY_MASTER!$A$4:$A$10,0)),"To Be Confirmed") -> To Be Confirmed | K17: Depends | L17: To Verify | M17: =IFERROR(INDEX(SERVICE_DOCUMENTS!$S$4:$S$1000,MATCH(A17,SERVICE_DOCUMENTS!$A$4:$A$1000,0))&"","") -> ✓ Aadhaar Card | N17: =IFERROR(INDEX(SERVICE_DOCUMENTS!$T$4:$T$1000,MATCH(A17,SERVICE_DOCUMENTS!$A$4:$A$1000,0))&"","") -> • Identity Proof (To Verify) • Address Proof (To Verify) | O17: Aadhaar holders whose details need correction, subject to UIDAI update limits. | P17: Step 1 → Bring your Aadhaar card and the supporting document (originals). Step 2 → Operator checks your current Aadhaar details and the document for the relationship / head of family detail change. Step 3 → Aadhaar holder gives fingerprint / biometric authentication at the centre. Step 4 → New relationship / head of family detail details are entered and shown to you for checking before submission. Step 5 → Pay the charge and collect the acknowledgement slip (URN) to track the update. | Q17: Depends on Department | R17: To Verify | S17: To Verify | T17: =IF(AND(OR(ISNUMBER(R17),R17="N/A"),OR(ISNUMBER(S17),S17="N/A"),OR(ISNUMBER(R17),ISNUMBER(S17))),N(R17)+N(S17),"To Verify") -> To Verify | U17: To Verify | V17: No | W17: Depends on Service | X17: Offline | Y17: No | AA17: Yes | AB17: Yes | AC17: To Verify | AD17: To Verify | AE17: No | AF17: To Verify | AG17: To Verify | AH17: No | AI17: No | AJ17: No | AK17: No | AL17: Aadhaar Centre | AM17: Demographic Update | AN17: =BA17&", "&AZ17 -> Aadhaar Relationship / Head of Family Detail Update, Aadhaar Centre, Devmobile Stores, आधार संबंध / परिवार मुखिया विवरण अपडेट, आधार सेंटर, सेवा | AO17: aadhaar-relationship-head-of-family-detail-update | AP17: ✏️ | AQ17: 140 | AR17: Q1: Do I need to come in person? A1: Yes, the Aadhaar holder normally gives biometric authentication at the centre. Q2: Is there a limit on changes? A2: UIDAI limits some updates. Ask the operator for the current rule. | AS17: Aadhaar services depend on UIDAI operator authorization. Please confirm with the shop before visiting. | AT17: Fees, documents and processing time are subject to change as per government / bank / portal rules. Final charges are confirmed at the shop before the service starts. | AV17: To Verify | AW17: Confirm whether this field is updatable under your authorization | AX17: Aadhaar Relationship / Head of Family Detail Update Service | Devmobile Stores | AY17: Aadhaar Relationship / Head of Family Detail Update (आधार संबंध / परिवार मुखिया विवरण अपडेट) at Devmobile Stores and Common Service Center & Aadhaar Centre. Check required documents, charges and process before you visit. | AZ17: आधार संबंध / परिवार मुखिया विवरण अपडेट, आधार सेंटर, सेवा | BA17: Aadhaar Relationship / Head of Family Detail Update, Aadhaar Centre, Devmobile Stores | BC17: =IFERROR(INDEX(CATEGORY_MASTER!$C$4:$C$30,MATCH(B17,CATEGORY_MASTER!$A$4:$A$30,0)),"") -> 🪪 | BD17: ="/services/"&AO17 -> /services/aadhaar-relationship-head-of-family-detail-update | BE17: =IF(AND(AH17="Yes",AG17="Active",I17<>"Not Available"),"LIVE","HIDDEN") -> HIDDEN | BF17: Correct Aadhaar details • Biometric-verified update • Acknowledgement slip | BG17: Check Documents | BH17: =B17&"|"&COUNTIF($B$4:B17,B17) -> Aadhaar Centre|14 | BI17: =IF(AND(AI17="Yes",BE17="LIVE"),COUNTIFS($AI$4:AI17,"Yes",$BE$4:BE17,"LIVE"),"") | BJ17: =IF(AND(AJ17="Yes",BE17="LIVE"),COUNTIFS($AJ$4:AJ17,"Yes",$BE$4:BE17,"LIVE"),"") | BK17: =IF(AND(AK17="Yes",BE17="LIVE"),COUNTIFS($AK$4:AK17,"Yes",$BE$4:BE17,"LIVE"),"") | BL17: =IF(I17="To Verify",COUNTIF($I$4:I17,"To Verify"),"") -> 4
A18: AAD-015 | B18: Aadhaar Centre | C18: Aadhaar Services | D18: Demographic Update | E18: Aadhaar Combined Demographic Update (Multiple Fields) | F18: आधार संयुक्त डेमोग्राफिक अपडेट (कई जानकारियाँ) | G18: Get Aadhaar Combined Demographic Update (Multiple Fields) done at our Aadhaar Centre. | H18: Update or correct the combined demographic recorded in your Aadhaar through the Aadhaar Centre. | I18: Available | J18: =IFERROR(INDEX(AVAILABILITY_MASTER!$C$4:$C$10,MATCH(I18,AVAILABILITY_MASTER!$A$4:$A$10,0)),"To Be Confirmed") -> Available | K18: Yes | L18: To Verify | M18: =IFERROR(INDEX(SERVICE_DOCUMENTS!$S$4:$S$1000,MATCH(A18,SERVICE_DOCUMENTS!$A$4:$A$1000,0))&"","") -> ✓ Aadhaar Card | N18: =IFERROR(INDEX(SERVICE_DOCUMENTS!$T$4:$T$1000,MATCH(A18,SERVICE_DOCUMENTS!$A$4:$A$1000,0))&"","") -> • Identity Proof (To Verify) • Address Proof (To Verify) | O18: Aadhaar holders whose details need correction, subject to UIDAI update limits. | P18: Step 1 → Bring your Aadhaar card and the supporting document (originals). Step 2 → Operator checks your current Aadhaar details and the document for the combined demographic change. Step 3 → Aadhaar holder gives fingerprint / biometric authentication at the centre. Step 4 → New combined demographic details are entered and shown to you for checking before submission. Step 5 → Pay the charge and collect the acknowledgement slip (URN) to track the update. | Q18: Depends on Department | R18: To Verify | S18: To Verify | T18: =IF(AND(OR(ISNUMBER(R18),R18="N/A"),OR(ISNUMBER(S18),S18="N/A"),OR(ISNUMBER(R18),ISNUMBER(S18))),N(R18)+N(S18),"To Verify") -> To Verify | U18: To Verify | V18: No | W18: Depends on Service | X18: Offline | Y18: No | AA18: Yes | AB18: Yes | AC18: To Verify | AD18: To Verify | AE18: No | AF18: To Verify | AG18: Active | AH18: Yes | AI18: No | AJ18: No | AK18: No | AL18: Aadhaar Centre | AM18: Demographic Update | AN18: =BA18&", "&AZ18 -> Aadhaar Combined Demographic Update (Multiple Fields), Aadhaar Centre, Devmobile Stores, आधार संयुक्त डेमोग्राफिक अपडेट (कई जानकारियाँ), आधार सेंटर, सेवा | AO18: aadhaar-combined-demographic-update-multiple-fields | AP18: ✏️ | AQ18: 150 | AR18: Q1: Do I need to come in person? A1: Yes, the Aadhaar holder normally gives biometric authentication at the centre. Q2: Is there a limit on changes? A2: UIDAI limits some updates. Ask the operator for the current rule. | AS18: Aadhaar services depend on UIDAI operator authorization. Please confirm with the shop before visiting. | AT18: Fees, documents and processing time are subject to change as per government / bank / portal rules. Final charges are confirmed at the shop before the service starts. | AV18: To Verify | AW18: Set to Available as per owner's example; authorization still To Verify. | AX18: Aadhaar Combined Demographic Update (Multiple Fields) Service | Devmobile Stores | AY18: Aadhaar Combined Demographic Update (Multiple Fields) (आधार संयुक्त डेमोग्राफिक अपडेट (कई जानकारियाँ)) at Devmobile Stores and Common Service Center & Aadhaar Centre. Check required documents, charges and process before you visit. | AZ18: आधार संयुक्त डेमोग्राफिक अपडेट (कई जानकारियाँ), आधार सेंटर, सेवा | BA18: Aadhaar Combined Demographic Update (Multiple Fields), Aadhaar Centre, Devmobile Stores | BC18: =IFERROR(INDEX(CATEGORY_MASTER!$C$4:$C$30,MATCH(B18,CATEGORY_MASTER!$A$4:$A$30,0)),"") -> 🪪 | BD18: ="/services/"&AO18 -> /services/aadhaar-combined-demographic-update-multiple-fields | BE18: =IF(AND(AH18="Yes",AG18="Active",I18<>"Not Available"),"LIVE","HIDDEN") -> LIVE | BF18: Correct Aadhaar details • Biometric-verified update • Acknowledgement slip | BG18: Check Documents | BH18: =B18&"|"&COUNTIF($B$4:B18,B18) -> Aadhaar Centre|15 | BI18: =IF(AND(AI18="Yes",BE18="LIVE"),COUNTIFS($AI$4:AI18,"Yes",$BE$4:BE18,"LIVE"),"") | BJ18: =IF(AND(AJ18="Yes",BE18="LIVE"),COUNTIFS($AJ$4:AJ18,"Yes",$BE$4:BE18,"LIVE"),"") | BK18: =IF(AND(AK18="Yes",BE18="LIVE"),COUNTIFS($AK$4:AK18,"Yes",$BE$4:BE18,"LIVE"),"") | BL18: =IF(I18="To Verify",COUNTIF($I$4:I18,"To Verify"),"")
